{
 "cells": [
  {
   "cell_type": "code",
   "execution_count": 13,
   "metadata": {},
   "outputs": [],
   "source": [
    "import numpy as np\n",
    "import math\n",
    "import tensorflow as tf"
   ]
  },
  {
   "cell_type": "code",
   "execution_count": 4,
   "metadata": {},
   "outputs": [],
   "source": [
    "from sklearn.linear_model import LinearRegression, Ridge\n",
    "from sklearn.preprocessing import StandardScaler, PolynomialFeatures\n",
    "from sklearn.model_selection import train_test_split"
   ]
  },
  {
   "cell_type": "code",
   "execution_count": 73,
   "metadata": {},
   "outputs": [],
   "source": [
    "from tensorflow.keras.models import Sequential\n",
    "from tensorflow.keras.layers import Dense,Flatten\n",
    "from tensorflow.keras.activations import relu,linear\n",
    "from tensorflow.keras.losses import SparseCategoricalCrossentropy\n",
    "from tensorflow.keras.optimizers import Adam"
   ]
  },
  {
   "cell_type": "code",
   "execution_count": 3,
   "metadata": {},
   "outputs": [],
   "source": [
    "def mse(y,y_):\n",
    "    m= len(y)\n",
    "    m = len(y)\n",
    "    dif = y_ -y\n",
    "    dif = dif*dif\n",
    "    mse = sum(dif)\n",
    "    mse/=(2*m)\n",
    "    return(mse)\n",
    "    \n"
   ]
  },
  {
   "cell_type": "code",
   "execution_count": 7,
   "metadata": {},
   "outputs": [
    {
     "name": "stderr",
     "output_type": "stream",
     "text": [
      "c:\\Users\\Asjad1\\Desktop\\ML\\assigment_utils.py:144: SyntaxWarning: invalid escape sequence '\\l'\n",
      "  ax[0].plot(x, y_pred[:,i],  lw=0.5, label=f\"$\\lambda =${lambda_range[i]}\")\n"
     ]
    }
   ],
   "source": [
    "from assigment_utils import *"
   ]
  },
  {
   "cell_type": "code",
   "execution_count": 81,
   "metadata": {},
   "outputs": [
    {
     "name": "stdout",
     "output_type": "stream",
     "text": [
      "(12, 1)\n"
     ]
    }
   ],
   "source": [
    "X,y,x_ideal,y_ideal = gen_data(18, 2, 0.7)\n",
    "X_train, X_test, y_train, y_test = train_test_split(X,y,test_size=0.33, random_state=1)\n",
    "X_train = X_train.reshape(-1, 1) \n",
    "print(X_train.shape)"
   ]
  },
  {
   "cell_type": "code",
   "execution_count": 48,
   "metadata": {},
   "outputs": [],
   "source": [
    "degree = 10\n",
    "lmodel = lin_model(degree)\n",
    "lmodel.fit(X_train, y_train)\n",
    "\n",
    "# predict on training data, find training error\n",
    "yhat = lmodel.predict(X_train)\n",
    "err_train = lmodel.mse(y_train, yhat)\n",
    "\n",
    "# predict on test data, find error\n",
    "yhat = lmodel.predict(X_test)\n",
    "err_test = lmodel.mse(y_test, yhat)\n"
   ]
  },
  {
   "cell_type": "code",
   "execution_count": 49,
   "metadata": {},
   "outputs": [
    {
     "name": "stdout",
     "output_type": "stream",
     "text": [
      "train error:  58.00756057277448 test error:  171215.01170007995\n"
     ]
    }
   ],
   "source": [
    "print(\"train error: \",err_train,\"test error: \",err_test)"
   ]
  },
  {
   "cell_type": "code",
   "execution_count": 50,
   "metadata": {},
   "outputs": [],
   "source": [
    "def category_error(y,y_):\n",
    "    m = len(y)\n",
    "    err =0\n",
    "    for i in range(m):\n",
    "        if y[i]!= y_[i]:\n",
    "            err+=1\n",
    "        err/=m\n",
    "\n",
    "    return err"
   ]
  },
  {
   "cell_type": "code",
   "execution_count": 82,
   "metadata": {},
   "outputs": [
    {
     "name": "stderr",
     "output_type": "stream",
     "text": [
      "C:\\Users\\Asjad1\\AppData\\Roaming\\Python\\Python312\\site-packages\\keras\\src\\layers\\reshaping\\flatten.py:37: UserWarning: Do not pass an `input_shape`/`input_dim` argument to a layer. When using Sequential models, prefer using an `Input(shape)` object as the first layer in the model instead.\n",
      "  super().__init__(**kwargs)\n"
     ]
    }
   ],
   "source": [
    "tf.random.set_seed(1234)\n",
    "model = Sequential(\n",
    "    [\n",
    "        Flatten(input_shape=(1,)),\n",
    "        Dense(units= 120,activation =\"relu\",kernel_regularizer=tf.keras.regularizers.l2(0.1)),\n",
    "        Dense(units=40,activation = \"relu\",kernel_regularizer=tf.keras.regularizers.l2(0.1)),\n",
    "        Dense(units= 6, activation = \"linear\"),\n",
    "\n",
    "        \n",
    "    ], name=None\n",
    ")\n"
   ]
  },
  {
   "cell_type": "code",
   "execution_count": 83,
   "metadata": {},
   "outputs": [],
   "source": [
    "model.compile(\n",
    "    \n",
    "    loss=tf.keras.losses.SparseCategoricalCrossentropy(from_logits=True),          \n",
    "    optimizer=tf.keras.optimizers.Adam(0.01),\n",
    "    \n",
    "    \n",
    "    \n",
    "\n",
    ")"
   ]
  },
  {
   "cell_type": "code",
   "execution_count": 84,
   "metadata": {},
   "outputs": [
    {
     "name": "stdout",
     "output_type": "stream",
     "text": [
      "Epoch 1/1000\n"
     ]
    },
    {
     "ename": "InvalidArgumentError",
     "evalue": "Graph execution error:\n\nDetected at node compile_loss/sparse_categorical_crossentropy/SparseSoftmaxCrossEntropyWithLogits/SparseSoftmaxCrossEntropyWithLogits defined at (most recent call last):\n  File \"<frozen runpy>\", line 198, in _run_module_as_main\n\n  File \"<frozen runpy>\", line 88, in _run_code\n\n  File \"C:\\Users\\Asjad1\\AppData\\Roaming\\Python\\Python312\\site-packages\\ipykernel_launcher.py\", line 18, in <module>\n\n  File \"C:\\Users\\Asjad1\\AppData\\Roaming\\Python\\Python312\\site-packages\\traitlets\\config\\application.py\", line 1075, in launch_instance\n\n  File \"C:\\Users\\Asjad1\\AppData\\Roaming\\Python\\Python312\\site-packages\\ipykernel\\kernelapp.py\", line 739, in start\n\n  File \"C:\\Users\\Asjad1\\AppData\\Roaming\\Python\\Python312\\site-packages\\tornado\\platform\\asyncio.py\", line 205, in start\n\n  File \"c:\\Python312\\Lib\\asyncio\\base_events.py\", line 641, in run_forever\n\n  File \"c:\\Python312\\Lib\\asyncio\\base_events.py\", line 1987, in _run_once\n\n  File \"c:\\Python312\\Lib\\asyncio\\events.py\", line 88, in _run\n\n  File \"C:\\Users\\Asjad1\\AppData\\Roaming\\Python\\Python312\\site-packages\\ipykernel\\kernelbase.py\", line 545, in dispatch_queue\n\n  File \"C:\\Users\\Asjad1\\AppData\\Roaming\\Python\\Python312\\site-packages\\ipykernel\\kernelbase.py\", line 534, in process_one\n\n  File \"C:\\Users\\Asjad1\\AppData\\Roaming\\Python\\Python312\\site-packages\\ipykernel\\kernelbase.py\", line 437, in dispatch_shell\n\n  File \"C:\\Users\\Asjad1\\AppData\\Roaming\\Python\\Python312\\site-packages\\ipykernel\\ipkernel.py\", line 362, in execute_request\n\n  File \"C:\\Users\\Asjad1\\AppData\\Roaming\\Python\\Python312\\site-packages\\ipykernel\\kernelbase.py\", line 778, in execute_request\n\n  File \"C:\\Users\\Asjad1\\AppData\\Roaming\\Python\\Python312\\site-packages\\ipykernel\\ipkernel.py\", line 449, in do_execute\n\n  File \"C:\\Users\\Asjad1\\AppData\\Roaming\\Python\\Python312\\site-packages\\ipykernel\\zmqshell.py\", line 549, in run_cell\n\n  File \"C:\\Users\\Asjad1\\AppData\\Roaming\\Python\\Python312\\site-packages\\IPython\\core\\interactiveshell.py\", line 3075, in run_cell\n\n  File \"C:\\Users\\Asjad1\\AppData\\Roaming\\Python\\Python312\\site-packages\\IPython\\core\\interactiveshell.py\", line 3130, in _run_cell\n\n  File \"C:\\Users\\Asjad1\\AppData\\Roaming\\Python\\Python312\\site-packages\\IPython\\core\\async_helpers.py\", line 129, in _pseudo_sync_runner\n\n  File \"C:\\Users\\Asjad1\\AppData\\Roaming\\Python\\Python312\\site-packages\\IPython\\core\\interactiveshell.py\", line 3334, in run_cell_async\n\n  File \"C:\\Users\\Asjad1\\AppData\\Roaming\\Python\\Python312\\site-packages\\IPython\\core\\interactiveshell.py\", line 3517, in run_ast_nodes\n\n  File \"C:\\Users\\Asjad1\\AppData\\Roaming\\Python\\Python312\\site-packages\\IPython\\core\\interactiveshell.py\", line 3577, in run_code\n\n  File \"C:\\Users\\Asjad1\\AppData\\Local\\Temp\\ipykernel_4436\\1969447389.py\", line 1, in <module>\n\n  File \"C:\\Users\\Asjad1\\AppData\\Roaming\\Python\\Python312\\site-packages\\keras\\src\\utils\\traceback_utils.py\", line 117, in error_handler\n\n  File \"C:\\Users\\Asjad1\\AppData\\Roaming\\Python\\Python312\\site-packages\\keras\\src\\backend\\tensorflow\\trainer.py\", line 314, in fit\n\n  File \"C:\\Users\\Asjad1\\AppData\\Roaming\\Python\\Python312\\site-packages\\keras\\src\\backend\\tensorflow\\trainer.py\", line 117, in one_step_on_iterator\n\n  File \"C:\\Users\\Asjad1\\AppData\\Roaming\\Python\\Python312\\site-packages\\keras\\src\\backend\\tensorflow\\trainer.py\", line 104, in one_step_on_data\n\n  File \"C:\\Users\\Asjad1\\AppData\\Roaming\\Python\\Python312\\site-packages\\keras\\src\\backend\\tensorflow\\trainer.py\", line 54, in train_step\n\n  File \"C:\\Users\\Asjad1\\AppData\\Roaming\\Python\\Python312\\site-packages\\keras\\src\\trainers\\trainer.py\", line 316, in compute_loss\n\n  File \"C:\\Users\\Asjad1\\AppData\\Roaming\\Python\\Python312\\site-packages\\keras\\src\\trainers\\compile_utils.py\", line 609, in __call__\n\n  File \"C:\\Users\\Asjad1\\AppData\\Roaming\\Python\\Python312\\site-packages\\keras\\src\\trainers\\compile_utils.py\", line 645, in call\n\n  File \"C:\\Users\\Asjad1\\AppData\\Roaming\\Python\\Python312\\site-packages\\keras\\src\\losses\\loss.py\", line 43, in __call__\n\n  File \"C:\\Users\\Asjad1\\AppData\\Roaming\\Python\\Python312\\site-packages\\keras\\src\\losses\\losses.py\", line 22, in call\n\n  File \"C:\\Users\\Asjad1\\AppData\\Roaming\\Python\\Python312\\site-packages\\keras\\src\\losses\\losses.py\", line 1722, in sparse_categorical_crossentropy\n\n  File \"C:\\Users\\Asjad1\\AppData\\Roaming\\Python\\Python312\\site-packages\\keras\\src\\ops\\nn.py\", line 1567, in sparse_categorical_crossentropy\n\n  File \"C:\\Users\\Asjad1\\AppData\\Roaming\\Python\\Python312\\site-packages\\keras\\src\\backend\\tensorflow\\nn.py\", line 638, in sparse_categorical_crossentropy\n\nReceived a label value of 2653 which is outside the valid range of [0, 6).  Label values: 0 563 183 1025 890 5 2391 2242 457 125 2653 901\n\t [[{{node compile_loss/sparse_categorical_crossentropy/SparseSoftmaxCrossEntropyWithLogits/SparseSoftmaxCrossEntropyWithLogits}}]] [Op:__inference_one_step_on_iterator_6204]",
     "output_type": "error",
     "traceback": [
      "\u001b[1;31m---------------------------------------------------------------------------\u001b[0m",
      "\u001b[1;31mInvalidArgumentError\u001b[0m                      Traceback (most recent call last)",
      "Cell \u001b[1;32mIn[84], line 1\u001b[0m\n\u001b[1;32m----> 1\u001b[0m \u001b[43mmodel\u001b[49m\u001b[38;5;241;43m.\u001b[39;49m\u001b[43mfit\u001b[49m\u001b[43m(\u001b[49m\n\u001b[0;32m      2\u001b[0m \u001b[43m    \u001b[49m\u001b[43mX_train\u001b[49m\u001b[43m,\u001b[49m\u001b[43m \u001b[49m\u001b[43my_train\u001b[49m\u001b[43m,\u001b[49m\n\u001b[0;32m      3\u001b[0m \u001b[43m    \u001b[49m\u001b[43mepochs\u001b[49m\u001b[38;5;241;43m=\u001b[39;49m\u001b[38;5;241;43m1000\u001b[39;49m\n\u001b[0;32m      4\u001b[0m \u001b[43m)\u001b[49m\n",
      "File \u001b[1;32m~\\AppData\\Roaming\\Python\\Python312\\site-packages\\keras\\src\\utils\\traceback_utils.py:122\u001b[0m, in \u001b[0;36mfilter_traceback.<locals>.error_handler\u001b[1;34m(*args, **kwargs)\u001b[0m\n\u001b[0;32m    119\u001b[0m     filtered_tb \u001b[38;5;241m=\u001b[39m _process_traceback_frames(e\u001b[38;5;241m.\u001b[39m__traceback__)\n\u001b[0;32m    120\u001b[0m     \u001b[38;5;66;03m# To get the full stack trace, call:\u001b[39;00m\n\u001b[0;32m    121\u001b[0m     \u001b[38;5;66;03m# `keras.config.disable_traceback_filtering()`\u001b[39;00m\n\u001b[1;32m--> 122\u001b[0m     \u001b[38;5;28;01mraise\u001b[39;00m e\u001b[38;5;241m.\u001b[39mwith_traceback(filtered_tb) \u001b[38;5;28;01mfrom\u001b[39;00m \u001b[38;5;28;01mNone\u001b[39;00m\n\u001b[0;32m    123\u001b[0m \u001b[38;5;28;01mfinally\u001b[39;00m:\n\u001b[0;32m    124\u001b[0m     \u001b[38;5;28;01mdel\u001b[39;00m filtered_tb\n",
      "File \u001b[1;32m~\\AppData\\Roaming\\Python\\Python312\\site-packages\\tensorflow\\python\\eager\\execute.py:53\u001b[0m, in \u001b[0;36mquick_execute\u001b[1;34m(op_name, num_outputs, inputs, attrs, ctx, name)\u001b[0m\n\u001b[0;32m     51\u001b[0m \u001b[38;5;28;01mtry\u001b[39;00m:\n\u001b[0;32m     52\u001b[0m   ctx\u001b[38;5;241m.\u001b[39mensure_initialized()\n\u001b[1;32m---> 53\u001b[0m   tensors \u001b[38;5;241m=\u001b[39m pywrap_tfe\u001b[38;5;241m.\u001b[39mTFE_Py_Execute(ctx\u001b[38;5;241m.\u001b[39m_handle, device_name, op_name,\n\u001b[0;32m     54\u001b[0m                                       inputs, attrs, num_outputs)\n\u001b[0;32m     55\u001b[0m \u001b[38;5;28;01mexcept\u001b[39;00m core\u001b[38;5;241m.\u001b[39m_NotOkStatusException \u001b[38;5;28;01mas\u001b[39;00m e:\n\u001b[0;32m     56\u001b[0m   \u001b[38;5;28;01mif\u001b[39;00m name \u001b[38;5;129;01mis\u001b[39;00m \u001b[38;5;129;01mnot\u001b[39;00m \u001b[38;5;28;01mNone\u001b[39;00m:\n",
      "\u001b[1;31mInvalidArgumentError\u001b[0m: Graph execution error:\n\nDetected at node compile_loss/sparse_categorical_crossentropy/SparseSoftmaxCrossEntropyWithLogits/SparseSoftmaxCrossEntropyWithLogits defined at (most recent call last):\n  File \"<frozen runpy>\", line 198, in _run_module_as_main\n\n  File \"<frozen runpy>\", line 88, in _run_code\n\n  File \"C:\\Users\\Asjad1\\AppData\\Roaming\\Python\\Python312\\site-packages\\ipykernel_launcher.py\", line 18, in <module>\n\n  File \"C:\\Users\\Asjad1\\AppData\\Roaming\\Python\\Python312\\site-packages\\traitlets\\config\\application.py\", line 1075, in launch_instance\n\n  File \"C:\\Users\\Asjad1\\AppData\\Roaming\\Python\\Python312\\site-packages\\ipykernel\\kernelapp.py\", line 739, in start\n\n  File \"C:\\Users\\Asjad1\\AppData\\Roaming\\Python\\Python312\\site-packages\\tornado\\platform\\asyncio.py\", line 205, in start\n\n  File \"c:\\Python312\\Lib\\asyncio\\base_events.py\", line 641, in run_forever\n\n  File \"c:\\Python312\\Lib\\asyncio\\base_events.py\", line 1987, in _run_once\n\n  File \"c:\\Python312\\Lib\\asyncio\\events.py\", line 88, in _run\n\n  File \"C:\\Users\\Asjad1\\AppData\\Roaming\\Python\\Python312\\site-packages\\ipykernel\\kernelbase.py\", line 545, in dispatch_queue\n\n  File \"C:\\Users\\Asjad1\\AppData\\Roaming\\Python\\Python312\\site-packages\\ipykernel\\kernelbase.py\", line 534, in process_one\n\n  File \"C:\\Users\\Asjad1\\AppData\\Roaming\\Python\\Python312\\site-packages\\ipykernel\\kernelbase.py\", line 437, in dispatch_shell\n\n  File \"C:\\Users\\Asjad1\\AppData\\Roaming\\Python\\Python312\\site-packages\\ipykernel\\ipkernel.py\", line 362, in execute_request\n\n  File \"C:\\Users\\Asjad1\\AppData\\Roaming\\Python\\Python312\\site-packages\\ipykernel\\kernelbase.py\", line 778, in execute_request\n\n  File \"C:\\Users\\Asjad1\\AppData\\Roaming\\Python\\Python312\\site-packages\\ipykernel\\ipkernel.py\", line 449, in do_execute\n\n  File \"C:\\Users\\Asjad1\\AppData\\Roaming\\Python\\Python312\\site-packages\\ipykernel\\zmqshell.py\", line 549, in run_cell\n\n  File \"C:\\Users\\Asjad1\\AppData\\Roaming\\Python\\Python312\\site-packages\\IPython\\core\\interactiveshell.py\", line 3075, in run_cell\n\n  File \"C:\\Users\\Asjad1\\AppData\\Roaming\\Python\\Python312\\site-packages\\IPython\\core\\interactiveshell.py\", line 3130, in _run_cell\n\n  File \"C:\\Users\\Asjad1\\AppData\\Roaming\\Python\\Python312\\site-packages\\IPython\\core\\async_helpers.py\", line 129, in _pseudo_sync_runner\n\n  File \"C:\\Users\\Asjad1\\AppData\\Roaming\\Python\\Python312\\site-packages\\IPython\\core\\interactiveshell.py\", line 3334, in run_cell_async\n\n  File \"C:\\Users\\Asjad1\\AppData\\Roaming\\Python\\Python312\\site-packages\\IPython\\core\\interactiveshell.py\", line 3517, in run_ast_nodes\n\n  File \"C:\\Users\\Asjad1\\AppData\\Roaming\\Python\\Python312\\site-packages\\IPython\\core\\interactiveshell.py\", line 3577, in run_code\n\n  File \"C:\\Users\\Asjad1\\AppData\\Local\\Temp\\ipykernel_4436\\1969447389.py\", line 1, in <module>\n\n  File \"C:\\Users\\Asjad1\\AppData\\Roaming\\Python\\Python312\\site-packages\\keras\\src\\utils\\traceback_utils.py\", line 117, in error_handler\n\n  File \"C:\\Users\\Asjad1\\AppData\\Roaming\\Python\\Python312\\site-packages\\keras\\src\\backend\\tensorflow\\trainer.py\", line 314, in fit\n\n  File \"C:\\Users\\Asjad1\\AppData\\Roaming\\Python\\Python312\\site-packages\\keras\\src\\backend\\tensorflow\\trainer.py\", line 117, in one_step_on_iterator\n\n  File \"C:\\Users\\Asjad1\\AppData\\Roaming\\Python\\Python312\\site-packages\\keras\\src\\backend\\tensorflow\\trainer.py\", line 104, in one_step_on_data\n\n  File \"C:\\Users\\Asjad1\\AppData\\Roaming\\Python\\Python312\\site-packages\\keras\\src\\backend\\tensorflow\\trainer.py\", line 54, in train_step\n\n  File \"C:\\Users\\Asjad1\\AppData\\Roaming\\Python\\Python312\\site-packages\\keras\\src\\trainers\\trainer.py\", line 316, in compute_loss\n\n  File \"C:\\Users\\Asjad1\\AppData\\Roaming\\Python\\Python312\\site-packages\\keras\\src\\trainers\\compile_utils.py\", line 609, in __call__\n\n  File \"C:\\Users\\Asjad1\\AppData\\Roaming\\Python\\Python312\\site-packages\\keras\\src\\trainers\\compile_utils.py\", line 645, in call\n\n  File \"C:\\Users\\Asjad1\\AppData\\Roaming\\Python\\Python312\\site-packages\\keras\\src\\losses\\loss.py\", line 43, in __call__\n\n  File \"C:\\Users\\Asjad1\\AppData\\Roaming\\Python\\Python312\\site-packages\\keras\\src\\losses\\losses.py\", line 22, in call\n\n  File \"C:\\Users\\Asjad1\\AppData\\Roaming\\Python\\Python312\\site-packages\\keras\\src\\losses\\losses.py\", line 1722, in sparse_categorical_crossentropy\n\n  File \"C:\\Users\\Asjad1\\AppData\\Roaming\\Python\\Python312\\site-packages\\keras\\src\\ops\\nn.py\", line 1567, in sparse_categorical_crossentropy\n\n  File \"C:\\Users\\Asjad1\\AppData\\Roaming\\Python\\Python312\\site-packages\\keras\\src\\backend\\tensorflow\\nn.py\", line 638, in sparse_categorical_crossentropy\n\nReceived a label value of 2653 which is outside the valid range of [0, 6).  Label values: 0 563 183 1025 890 5 2391 2242 457 125 2653 901\n\t [[{{node compile_loss/sparse_categorical_crossentropy/SparseSoftmaxCrossEntropyWithLogits/SparseSoftmaxCrossEntropyWithLogits}}]] [Op:__inference_one_step_on_iterator_6204]"
     ]
    }
   ],
   "source": [
    "model.fit(\n",
    "    X_train, y_train,\n",
    "    epochs=1000\n",
    ")"
   ]
  },
  {
   "cell_type": "code",
   "execution_count": null,
   "metadata": {},
   "outputs": [],
   "source": [
    "model.summary()\n"
   ]
  },
  {
   "cell_type": "code",
   "execution_count": null,
   "metadata": {},
   "outputs": [],
   "source": [
    "tf.random.set_seed(1234)\n",
    "lambdas = [0.0, 0.001, 0.01, 0.05, 0.1, 0.2, 0.3]\n",
    "models=[None] * len(lambdas)\n",
    "\n",
    "for i in range(len(lambdas)):\n",
    "    lambda_ = lambdas[i]\n",
    "    models[i] =  Sequential(\n",
    "        [\n",
    "            Dense(120, activation = 'relu', kernel_regularizer=tf.keras.regularizers.l2(lambda_)),\n",
    "            Dense(40, activation = 'relu', kernel_regularizer=tf.keras.regularizers.l2(lambda_)),\n",
    "            Dense(classes, activation = 'linear')\n",
    "        ]\n",
    "    )\n",
    "    models[i].compile(\n",
    "        loss=tf.keras.losses.SparseCategoricalCrossentropy(from_logits=True),\n",
    "        optimizer=tf.keras.optimizers.Adam(0.01),\n",
    "    )\n",
    "\n",
    "    models[i].fit(\n",
    "        X_train,y_train,\n",
    "        epochs=1000\n",
    "    )\n",
    "    print(f\"Finished lambda = {lambda_}\")\n"
   ]
  }
 ],
 "metadata": {
  "kernelspec": {
   "display_name": "Python 3",
   "language": "python",
   "name": "python3"
  },
  "language_info": {
   "codemirror_mode": {
    "name": "ipython",
    "version": 3
   },
   "file_extension": ".py",
   "mimetype": "text/x-python",
   "name": "python",
   "nbconvert_exporter": "python",
   "pygments_lexer": "ipython3",
   "version": "3.12.3"
  }
 },
 "nbformat": 4,
 "nbformat_minor": 2
}
